Workbook

Sheet Dashboard
B2: 🎯 DSA MASTERY TRACKER
B5: =COUNTA('DSA Problem Tracker'!C:C,'Company Questions'!C:C)-2 -> 288 | D5: =COUNTIF('DSA Problem Tracker'!E:E,"Solved")+COUNTIF('Company Questions'!F:F,"Solved") -> 0 | F5: =COUNTIF('DSA Problem Tracker'!E:E,"In Progress")+COUNTIF('Company Questions'!F:F,"In Progress") -> 0 | H5: =B5-D5-F5 -> 288 | J5: =IF(B5>0,D5/B5,0) -> 0
B7: Total Problems | D7: ✓ Solved | F7: ⚡ In Progress | H7: 📋 Remaining | J7: 🎯 Complete
B10: 📅 This Week | E10: 📆 This Month | H10: 🔥 Last Solved
B11: =COUNTIFS('DSA Problem Tracker'!F:F,">="&TODAY()-7,'DSA Problem Tracker'!F:F,"<="&TODAY())+COUNTIFS('Company Questions'!G:G,">="&TODAY()-7,'Company Questions'!G:G,"<="&TODAY()) -> 0 | E11: =COUNTIFS('DSA Problem Tracker'!F:F,">="&DATE(YEAR(TODAY()),MONTH(TODAY()),1),'DSA Problem Tracker'!F:F,"<="&TODAY())+COUNTIFS('Company Questions'!G:G,">="&DATE(YEAR(TODAY()),MONTH(TODAY()),1),'Company Questions'!G:G,"<="&TODAY()) -> 0 | H11: =MAX('DSA Problem Tracker'!F:F,'Company Questions'!G:G) -> 0
B14: ⚡ DIFFICULTY BREAKDOWN
C15: Total | D15: Solved | E15: In Progress | F15: Remaining | G15: % Done
B16: 🟢 Easy | C16: =COUNTIF('DSA Problem Tracker'!D:D,"Easy")+COUNTIF('Company Questions'!D:D,"Easy") -> 31 | D16: =COUNTIFS('DSA Problem Tracker'!D:D,"Easy",'DSA Problem Tracker'!E:E,"Solved")+COUNTIFS('Company Questions'!D:D,"Easy",'Company Questions'!F:F,"Solved") -> 0 | E16: =COUNTIFS('DSA Problem Tracker'!D:D,"Easy",'DSA Problem Tracker'!E:E,"In Progress")+COUNTIFS('Company Questions'!D:D,"Easy",'Company Questions'!F:F,"In Progress") -> 0 | F16: =C16-D16-E16 -> 31 | G16: =IF(C16>0,D16/C16,0) -> 0
B17: 🟡 Medium | C17: =COUNTIF('DSA Problem Tracker'!D:D,"Medium")+COUNTIF('Company Questions'!D:D,"Medium") -> 203 | D17: =COUNTIFS('DSA Problem Tracker'!D:D,"Medium",'DSA Problem Tracker'!E:E,"Solved")+COUNTIFS('Company Questions'!D:D,"Medium",'Company Questions'!F:F,"Solved") -> 0 | E17: =COUNTIFS('DSA Problem Tracker'!D:D,"Medium",'DSA Problem Tracker'!E:E,"In Progress")+COUNTIFS('Company Questions'!D:D,"Medium",'Company Questions'!F:F,"In Progress") -> 0 | F17: =C17-D17-E17 -> 203 | G17: =IF(C17>0,D17/C17,0) -> 0
B18: 🔴 Hard | C18: =COUNTIF('DSA Problem Tracker'!D:D,"Hard")+COUNTIF('Company Questions'!D:D,"Hard") -> 54 | D18: =COUNTIFS('DSA Problem Tracker'!D:D,"Hard",'DSA Problem Tracker'!E:E,"Solved")+COUNTIFS('Company Questions'!D:D,"Hard",'Company Questions'!F:F,"Solved") -> 0 | E18: =COUNTIFS('DSA Problem Tracker'!D:D,"Hard",'DSA Problem Tracker'!E:E,"In Progress")+COUNTIFS('Company Questions'!D:D,"Hard",'Company Questions'!F:F,"In Progress") -> 0 | F18: =C18-D18-E18 -> 54 | G18: =IF(C18>0,D18/C18,0) -> 0
B21: 🏢 COMPANY-WISE PROGRESS
B22: Company | C22: Total | D22: Solved | E22: Progress | F22: Complete
B23: Google | C23: =COUNTIF('Company Questions'!B:B,"Google") -> 1 | D23: =COUNTIFS('Company Questions'!B:B,"Google",'Company Questions'!F:F,"Solved") -> 0 | E23: =COUNTIFS('Company Questions'!B:B,"Google",'Company Questions'!F:F,"In Progress") -> 0 | F23: =IF(C23>0,D23/C23,0) -> 0
B24: Amazon | C24: =COUNTIF('Company Questions'!B:B,"Amazon") -> 1 | D24: =COUNTIFS('Company Questions'!B:B,"Amazon",'Company Questions'!F:F,"Solved") -> 0 | E24: =COUNTIFS('Company Questions'!B:B,"Amazon",'Company Questions'!F:F,"In Progress") -> 0 | F24: =IF(C24>0,D24/C24,0) -> 0
B25: Microsoft | C25: =COUNTIF('Company Questions'!B:B,"Microsoft") -> 1 | D25: =COUNTIFS('Company Questions'!B:B,"Microsoft",'Company Questions'!F:F,"Solved") -> 0 | E25: =COUNTIFS('Company Questions'!B:B,"Microsoft",'Company Questions'!F:F,"In Progress") -> 0 | F25: =IF(C25>0,D25/C25,0) -> 0
B26: Meta | C26: =COUNTIF('Company Questions'!B:B,"Meta") -> 1 | D26: =COUNTIFS('Company Questions'!B:B,"Meta",'Company Questions'!F:F,"Solved") -> 0 | E26: =COUNTIFS('Company Questions'!B:B,"Meta",'Company Questions'!F:F,"In Progress") -> 0 | F26: =IF(C26>0,D26/C26,0) -> 0
B27: Apple | C27: =COUNTIF('Company Questions'!B:B,"Apple") -> 1 | D27: =COUNTIFS('Company Questions'!B:B,"Apple",'Company Questions'!F:F,"Solved") -> 0 | E27: =COUNTIFS('Company Questions'!B:B,"Apple",'Company Questions'!F:F,"In Progress") -> 0 | F27: =IF(C27>0,D27/C27,0) -> 0
B28: Netflix | C28: =COUNTIF('Company Questions'!B:B,"Netflix") -> 1 | D28: =COUNTIFS('Company Questions'!B:B,"Netflix",'Company Questions'!F:F,"Solved") -> 0 | E28: =COUNTIFS('Company Questions'!B:B,"Netflix",'Company Questions'!F:F,"In Progress") -> 0 | F28: =IF(C28>0,D28/C28,0) -> 0
B29: Adobe | C29: =COUNTIF('Company Questions'!B:B,"Adobe") -> 1 | D29: =COUNTIFS('Company Questions'!B:B,"Adobe",'Company Questions'!F:F,"Solved") -> 0 | E29: =COUNTIFS('Company Questions'!B:B,"Adobe",'Company Questions'!F:F,"In Progress") -> 0 | F29: =IF(C29>0,D29/C29,0) -> 0
B30: Uber | C30: =COUNTIF('Company Questions'!B:B,"Uber") -> 1 | D30: =COUNTIFS('Company Questions'!B:B,"Uber",'Company Questions'!F:F,"Solved") -> 0 | E30: =COUNTIFS('Company Questions'!B:B,"Uber",'Company Questions'!F:F,"In Progress") -> 0 | F30: =IF(C30>0,D30/C30,0) -> 0
B31: LinkedIn | C31: =COUNTIF('Company Questions'!B:B,"LinkedIn") -> 1 | D31: =COUNTIFS('Company Questions'!B:B,"LinkedIn",'Company Questions'!F:F,"Solved") -> 0 | E31: =COUNTIFS('Company Questions'!B:B,"LinkedIn",'Company Questions'!F:F,"In Progress") -> 0 | F31: =IF(C31>0,D31/C31,0) -> 0
B32: Salesforce | C32: =COUNTIF('Company Questions'!B:B,"Salesforce") -> 1 | D32: =COUNTIFS('Company Questions'!B:B,"Salesforce",'Company Questions'!F:F,"Solved") -> 0 | E32: =COUNTIFS('Company Questions'!B:B,"Salesforce",'Company Questions'!F:F,"In Progress") -> 0 | F32: =IF(C32>0,D32/C32,0) -> 0
B34: 📚 TOP PATTERNS TO MASTER
B35: Pattern | C35: Total | D35: Solved | E35: Progress | F35: %
B36: 🔄 Sliding Window | C36: 13 | D36: =COUNTIFS('DSA Problem Tracker'!B:B,"*Sliding Window*",'DSA Problem Tracker'!E:E,"Solved") -> 0 | E36: =COUNTIFS('DSA Problem Tracker'!B:B,"*Sliding Window*",'DSA Problem Tracker'!E:E,"In Progress") -> 0 | F36: =IF(C36>0,D36/C36,0) -> 0
B37: 💎 Dynamic Programming | C37: 49 | D37: =COUNTIFS('DSA Problem Tracker'!B:B,"*Dynamic Programming*",'DSA Problem Tracker'!E:E,"Solved") -> 0 | E37: =COUNTIFS('DSA Problem Tracker'!B:B,"*Dynamic Programming*",'DSA Problem Tracker'!E:E,"In Progress") -> 0 | F37: =IF(C37>0,D37/C37,0) -> 0
B38: 🌳 Trees | C38: 32 | D38: =COUNTIFS('DSA Problem Tracker'!B:B,"*Trees*",'DSA Problem Tracker'!E:E,"Solved") -> 0 | E38: =COUNTIFS('DSA Problem Tracker'!B:B,"*Trees*",'DSA Problem Tracker'!E:E,"In Progress") -> 0 | F38: =IF(C38>0,D38/C38,0) -> 0
B39: 🕸️ Graphs | C39: 13 | D39: =COUNTIFS('DSA Problem Tracker'!B:B,"*Graphs*",'DSA Problem Tracker'!E:E,"Solved") -> 0 | E39: =COUNTIFS('DSA Problem Tracker'!B:B,"*Graphs*",'DSA Problem Tracker'!E:E,"In Progress") -> 0 | F39: =IF(C39>0,D39/C39,0) -> 0
B40: ↩️ Backtracking | C40: 7 | D40: =COUNTIFS('DSA Problem Tracker'!B:B,"*Backtracking*",'DSA Problem Tracker'!E:E,"Solved") -> 0 | E40: =COUNTIFS('DSA Problem Tracker'!B:B,"*Backtracking*",'DSA Problem Tracker'!E:E,"In Progress") -> 0 | F40: =IF(C40>0,D40/C40,0) -> 0
B41: 👉 Two Pointers | C41: 6 | D41: =COUNTIFS('DSA Problem Tracker'!B:B,"*Two Pointers*",'DSA Problem Tracker'!E:E,"Solved") -> 0 | E41: =COUNTIFS('DSA Problem Tracker'!B:B,"*Two Pointers*",'DSA Problem Tracker'!E:E,"In Progress") -> 0 | F41: =IF(C41>0,D41/C41,0) -> 0
B42: 🔍 Binary Search | C42: 9 | D42: =COUNTIFS('DSA Problem Tracker'!B:B,"*Binary Search*",'DSA Problem Tracker'!E:E,"Solved") -> 0 | E42: =COUNTIFS('DSA Problem Tracker'!B:B,"*Binary Search*",'DSA Problem Tracker'!E:E,"In Progress") -> 0 | F42: =IF(C42>0,D42/C42,0) -> 0
B43: 🚶 BFS/DFS | C43: 9 | D43: =COUNTIFS('DSA Problem Tracker'!B:B,"*BFS/DFS*",'DSA Problem Tracker'!E:E,"Solved") -> 0 | E43: =COUNTIFS('DSA Problem Tracker'!B:B,"*BFS/DFS*",'DSA Problem Tracker'!E:E,"In Progress") -> 0 | F43: =IF(C43>0,D43/C43,0) -> 0
B44: 📊 Heaps & Stacks | C44: 13 | D44: =COUNTIFS('DSA Problem Tracker'!B:B,"*Heaps & Stacks*",'DSA Problem Tracker'!E:E,"Solved") -> 0 | E44: =COUNTIFS('DSA Problem Tracker'!B:B,"*Heaps & Stacks*",'DSA Problem Tracker'!E:E,"In Progress") -> 0 | F44: =IF(C44>0,D44/C44,0) -> 0
B45: 🔗 Linked List | C45: 7 | D45: =COUNTIFS('DSA Problem Tracker'!B:B,"*Linked List*",'DSA Problem Tracker'!E:E,"Solved") -> 0 | E45: =COUNTIFS('DSA Problem Tracker'!B:B,"*Linked List*",'DSA Problem Tracker'!E:E,"In Progress") -> 0 | F45: =IF(C45>0,D45/C45,0) -> 0
B47: 💡 TIP: When you mark a problem as 'Solved' in DSA Problem Tracker, it automatically marks the same problem in Company Questions! Use the dropdown in Status columns to select: Not Started, In Progress, or Solved. Dashboard updates automatically!

Sheet DSA Problem Tracker
A1: # | B1: Pattern/Technique | C1: Problem Name | D1: Difficulty | E1: Status | F1: Date Solved | G1: Notes | H1: Revisit
A2: 1 | B2: Fast and Slow Pointer | C2: Linked List Cycle II | D2: Medium
A3: 2 | C3: Remove nth Node from the End of List | D3: Medium
A4: 3 | C4: Find the Duplicate Number | D4: Medium
A5: 4 | C5: Palindrome Linked List | D5: Easy
A6: 5 | B6: Overlapping Intervals | C6: Merge Intervals | D6: Medium
A7: 6 | C7: Insert Interval | D7: Medium
A8: 7 | C8: My Calendar II | D8: Medium
A9: 8 | C9: Minimum Number of Arrows to Burst Balloons | D9: Medium
A10: 9 | C10: Non-overlapping Intervals | D10: Medium
A11: 10 | B11: Prefix Sum | C11: Find the Middle Index in Array | D11: Easy
A12: 11 | C12: Product of Array Except Self | D12: Medium
A13: 12 | C13: Maximum Product Subarray | D13: Medium
A14: 13 | C14: Number of Ways to Split Array | D14: Medium
A15: 14 | C15: Range Sum Query 2D | D15: Medium
A16: 15 | B16: Sliding Window - Fixed Size | C16: Maximum Sum Subarray of Size K | D16: Easy
A17: 16 | C17: Number of Subarrays Having Average Greater or Equal to Threshold | D17: Medium
A18: 17 | C18: Repeated DNA Sequences | D18: Medium
A19: 18 | C19: Permutation in String | D19: Medium
A20: 19 | C20: Sliding Subarray Beauty | D20: Medium
A21: 20 | C21: Sliding Window Maximum | D21: Hard
A22: 21 | B22: Sliding Window - Variable Size | C22: Longest Substring Without Repeating Characters | D22: Medium
A23: 22 | C23: Minimum Size Subarray Sum | D23: Medium
A24: 23 | C24: Subarray Product Less Than K | D24: Medium
A25: 24 | C25: Max Consecutive Ones | D25: Easy
A26: 25 | C26: Fruits Into Baskets | D26: Medium
A27: 26 | C27: Count Number of Nice Subarrays | D27: Medium
A28: 27 | C28: Minimum Window Substring | D28: Hard
A29: 28 | B29: Two Pointers | C29: Two Sum II - Input Array is Sorted | D29: Medium
A30: 29 | C30: Sort Colors | D30: Medium
A31: 30 | C31: Next Permutation | D31: Medium
A32: 31 | C32: Bag of Tokens | D32: Medium
A33: 32 | C33: Container with Most Water | D33: Medium
A34: 33 | C34: Trapping Rain Water | D34: Hard
A35: 34 | B35: Cyclic Sort | C35: Missing Number | D35: Easy
A36: 35 | C36: Find Missing Numbers | D36: Easy
A37: 36 | C37: Set Mismatch | D37: Easy
A38: 37 | C38: First Missing Positive | D38: Hard
A39: 38 | B39: Reversal of Linked List | C39: Reverse Linked List | D39: Easy
A40: 39 | C40: Reverse Nodes in k-Group | D40: Hard
...

Sheet Company Questions
A1: # | B1: Company | C1: Problem Name | D1: Difficulty | E1: Pattern | F1: Status | G1: Date Solved | H1: Notes | I1: Revisit
A2: 1 | B2: Google | C2: Longest Substring Without Repeating Characters | D2: Medium | E2: Sliding Window | F2: =IF(COUNTIFS('DSA Problem Tracker'!$C:$C,C2,'DSA Problem Tracker'!$E:$E,"Solved")>0,"Solved","") | G2: =IF(F2="Solved",IF(COUNTIFS('DSA Problem Tracker'!$C:$C,C2,'DSA Problem Tracker'!$E:$E,"Solved")>0,INDEX('DSA Problem Tracker'!$F:$F,MATCH(C2,'DSA Problem Tracker'!$C:$C,0)),TODAY()),"")
A3: 2 | C3: Container With Most Water | D3: Medium | E3: Two Pointers | F3: =IF(COUNTIFS('DSA Problem Tracker'!$C:$C,C3,'DSA Problem Tracker'!$E:$E,"Solved")>0,"Solved","") | G3: =IF(F3="Solved",IF(COUNTIFS('DSA Problem Tracker'!$C:$C,C3,'DSA Problem Tracker'!$E:$E,"Solved")>0,INDEX('DSA Problem Tracker'!$F:$F,MATCH(C3,'DSA Problem Tracker'!$C:$C,0)),TODAY()),"")
A4: 3 | C4: Merge Intervals | D4: Medium | E4: Intervals | F4: =IF(COUNTIFS('DSA Problem Tracker'!$C:$C,C4,'DSA Problem Tracker'!$E:$E,"Solved")>0,"Solved","") | G4: =IF(F4="Solved",IF(COUNTIFS('DSA Problem Tracker'!$C:$C,C4,'DSA Problem Tracker'!$E:$E,"Solved")>0,INDEX('DSA Problem Tracker'!$F:$F,MATCH(C4,'DSA Problem Tracker'!$C:$C,0)),TODAY()),"")
A5: 4 | C5: LRU Cache | D5: Medium | E5: Design | F5: =IF(COUNTIFS('DSA Problem Tracker'!$C:$C,C5,'DSA Problem Tracker'!$E:$E,"Solved")>0,"Solved","") | G5: =IF(F5="Solved",IF(COUNTIFS('DSA Problem Tracker'!$C:$C,C5,'DSA Problem Tracker'!$E:$E,"Solved")>0,INDEX('DSA Problem Tracker'!$F:$F,MATCH(C5,'DSA Problem Tracker'!$C:$C,0)),TODAY()),"")
A6: 5 | C6: Word Ladder | D6: Hard | E6: BFS | F6: =IF(COUNTIFS('DSA Problem Tracker'!$C:$C,C6,'DSA Problem Tracker'!$E:$E,"Solved")>0,"Solved","") | G6: =IF(F6="Solved",IF(COUNTIFS('DSA Problem Tracker'!$C:$C,C6,'DSA Problem Tracker'!$E:$E,"Solved")>0,INDEX('DSA Problem Tracker'!$F:$F,MATCH(C6,'DSA Problem Tracker'!$C:$C,0)),TODAY()),"")
A7: 6 | C7: Trapping Rain Water | D7: Hard | E7: Two Pointers | F7: =IF(COUNTIFS('DSA Problem Tracker'!$C:$C,C7,'DSA Problem Tracker'!$E:$E,"Solved")>0,"Solved","") | G7: =IF(F7="Solved",IF(COUNTIFS('DSA Problem Tracker'!$C:$C,C7,'DSA Problem Tracker'!$E:$E,"Solved")>0,INDEX('DSA Problem Tracker'!$F:$F,MATCH(C7,'DSA Problem Tracker'!$C:$C,0)),TODAY()),"")
A8: 7 | C8: Median of Two Sorted Arrays | D8: Hard | E8: Binary Search | F8: =IF(COUNTIFS('DSA Problem Tracker'!$C:$C,C8,'DSA Problem Tracker'!$E:$E,"Solved")>0,"Solved","") | G8: =IF(F8="Solved",IF(COUNTIFS('DSA Problem Tracker'!$C:$C,C8,'DSA Problem Tracker'!$E:$E,"Solved")>0,INDEX('DSA Problem Tracker'!$F:$F,MATCH(C8,'DSA Problem Tracker'!$C:$C,0)),TODAY()),"")
A9: 8 | C9: Serialize and Deserialize Binary Tree | D9: Hard | E9: Trees | F9: =IF(COUNTIFS('DSA Problem Tracker'!$C:$C,C9,'DSA Problem Tracker'!$E:$E,"Solved")>0,"Solved","") | G9: =IF(F9="Solved",IF(COUNTIFS('DSA Problem Tracker'!$C:$C,C9,'DSA Problem Tracker'!$E:$E,"Solved")>0,INDEX('DSA Problem Tracker'!$F:$F,MATCH(C9,'DSA Problem Tracker'!$C:$C,0)),TODAY()),"")
A10: 9 | C10: Number of Islands | D10: Medium | E10: DFS/BFS | F10: =IF(COUNTIFS('DSA Problem Tracker'!$C:$C,C10,'DSA Problem Tracker'!$E:$E,"Solved")>0,"Solved","") | G10: =IF(F10="Solved",IF(COUNTIFS('DSA Problem Tracker'!$C:$C,C10,'DSA Problem Tracker'!$E:$E,"Solved")>0,INDEX('DSA Problem Tracker'!$F:$F,MATCH(C10,'DSA Problem Tracker'!$C:$C,0)),TODAY()),"")
A11: 10 | C11: Valid Parentheses | D11: Easy | E11: Stack | F11: =IF(COUNTIFS('DSA Problem Tracker'!$C:$C,C11,'DSA Problem Tracker'!$E:$E,"Solved")>0,"Solved","") | G11: =IF(F11="Solved",IF(COUNTIFS('DSA Problem Tracker'!$C:$C,C11,'DSA Problem Tracker'!$E:$E,"Solved")>0,INDEX('DSA Problem Tracker'!$F:$F,MATCH(C11,'DSA Problem Tracker'!$C:$C,0)),TODAY()),"")
A12: 11 | B12: Amazon | C12: Two Sum | D12: Easy | E12: Hash Map | F12: =IF(COUNTIFS('DSA Problem Tracker'!$C:$C,C12,'DSA Problem Tracker'!$E:$E,"Solved")>0,"Solved","") | G12: =IF(F12="Solved",IF(COUNTIFS('DSA Problem Tracker'!$C:$C,C12,'DSA Problem Tracker'!$E:$E,"Solved")>0,INDEX('DSA Problem Tracker'!$F:$F,MATCH(C12,'DSA Problem Tracker'!$C:$C,0)),TODAY()),"")
A13: 12 | C13: Product of Array Except Self | D13: Medium | E13: Prefix Sum | F13: =IF(COUNTIFS('DSA Problem Tracker'!$C:$C,C13,'DSA Problem Tracker'!$E:$E,"Solved")>0,"Solved","") | G13: =IF(F13="Solved",IF(COUNTIFS('DSA Problem Tracker'!$C:$C,C13,'DSA Problem Tracker'!$E:$E,"Solved")>0,INDEX('DSA Problem Tracker'!$F:$F,MATCH(C13,'DSA Problem Tracker'!$C:$C,0)),TODAY()),"")
A14: 13 | C14: Merge K Sorted Lists | D14: Hard | E14: K-way Merge | F14: =IF(COUNTIFS('DSA Problem Tracker'!$C:$C,C14,'DSA Problem Tracker'!$E:$E,"Solved")>0,"Solved","") | G14: =IF(F14="Solved",IF(COUNTIFS('DSA Problem Tracker'!$C:$C,C14,'DSA Problem Tracker'!$E:$E,"Solved")>0,INDEX('DSA Problem Tracker'!$F:$F,MATCH(C14,'DSA Problem Tracker'!$C:$C,0)),TODAY()),"")
A15: 14 | C15: LRU Cache | D15: Medium | E15: Design | F15: =IF(COUNTIFS('DSA Problem Tracker'!$C:$C,C15,'DSA Problem Tracker'!$E:$E,"Solved")>0,"Solved","") | G15: =IF(F15="Solved",IF(COUNTIFS('DSA Problem Tracker'!$C:$C,C15,'DSA Problem Tracker'!$E:$E,"Solved")>0,INDEX('DSA Problem Tracker'!$F:$F,MATCH(C15,'DSA Problem Tracker'!$C:$C,0)),TODAY()),"")
A16: 15 | C16: Word Break | D16: Medium | E16: DP | F16: =IF(COUNTIFS('DSA Problem Tracker'!$C:$C,C16,'DSA Problem Tracker'!$E:$E,"Solved")>0,"Solved","") | G16: =IF(F16="Solved",IF(COUNTIFS('DSA Problem Tracker'!$C:$C,C16,'DSA Problem Tracker'!$E:$E,"Solved")>0,INDEX('DSA Problem Tracker'!$F:$F,MATCH(C16,'DSA Problem Tracker'!$C:$C,0)),TODAY()),"")
A17: 16 | C17: Top K Frequent Elements | D17: Medium | E17: Heap | F17: =IF(COUNTIFS('DSA Problem Tracker'!$C:$C,C17,'DSA Problem Tracker'!$E:$E,"Solved")>0,"Solved","") | G17: =IF(F17="Solved",IF(COUNTIFS('DSA Problem Tracker'!$C:$C,C17,'DSA Problem Tracker'!$E:$E,"Solved")>0,INDEX('DSA Problem Tracker'!$F:$F,MATCH(C17,'DSA Problem Tracker'!$C:$C,0)),TODAY()),"")
A18: 17 | C18: Copy List with Random Pointer | D18: Medium | E18: Linked List | F18: =IF(COUNTIFS('DSA Problem Tracker'!$C:$C,C18,'DSA Problem Tracker'!$E:$E,"Solved")>0,"Solved","") | G18: =IF(F18="Solved",IF(COUNTIFS('DSA Problem Tracker'!$C:$C,C18,'DSA Problem Tracker'!$E:$E,"Solved")>0,INDEX('DSA Problem Tracker'!$F:$F,MATCH(C18,'DSA Problem Tracker'!$C:$C,0)),TODAY()),"")
A19: 18 | C19: Min Cost to Connect All Points | D19: Medium | E19: Graph | F19: =IF(COUNTIFS('DSA Problem Tracker'!$C:$C,C19,'DSA Problem Tracker'!$E:$E,"Solved")>0,"Solved","") | G19: =IF(F19="Solved",IF(COUNTIFS('DSA Problem Tracker'!$C:$C,C19,'DSA Problem Tracker'!$E:$E,"Solved")>0,INDEX('DSA Problem Tracker'!$F:$F,MATCH(C19,'DSA Problem Tracker'!$C:$C,0)),TODAY()),"")
A20: 19 | C20: Number of Provinces | D20: Medium | E20: Union Find | F20: =IF(COUNTIFS('DSA Problem Tracker'!$C:$C,C20,'DSA Problem Tracker'!$E:$E,"Solved")>0,"Solved","") | G20: =IF(F20="Solved",IF(COUNTIFS('DSA Problem Tracker'!$C:$C,C20,'DSA Problem Tracker'!$E:$E,"Solved")>0,INDEX('DSA Problem Tracker'!$F:$F,MATCH(C20,'DSA Problem Tracker'!$C:$C,0)),TODAY()),"")
A21: 20 | C21: Critical Connections in a Network | D21: Hard | E21: Graph | F21: =IF(COUNTIFS('DSA Problem Tracker'!$C:$C,C21,'DSA Problem Tracker'!$E:$E,"Solved")>0,"Solved","") | G21: =IF(F21="Solved",IF(COUNTIFS('DSA Problem Tracker'!$C:$C,C21,'DSA Problem Tracker'!$E:$E,"Solved")>0,INDEX('DSA Problem Tracker'!$F:$F,MATCH(C21,'DSA Problem Tracker'!$C:$C,0)),TODAY()),"")
A22: 21 | B22: Microsoft | C22: Reverse Linked List | D22: Easy | E22: Linked List | F22: =IF(COUNTIFS('DSA Problem Tracker'!$C:$C,C22,'DSA Problem Tracker'!$E:$E,"Solved")>0,"Solved","") | G22: =IF(F22="Solved",IF(COUNTIFS('DSA Problem Tracker'!$C:$C,C22,'DSA Problem Tracker'!$E:$E,"Solved")>0,INDEX('DSA Problem Tracker'!$F:$F,MATCH(C22,'DSA Problem Tracker'!$C:$C,0)),TODAY()),"")
A23: 22 | C23: Excel Sheet Column Number | D23: Easy | E23: Math | F23: =IF(COUNTIFS('DSA Problem Tracker'!$C:$C,C23,'DSA Problem Tracker'!$E:$E,"Solved")>0,"Solved","") | G23: =IF(F23="Solved",IF(COUNTIFS('DSA Problem Tracker'!$C:$C,C23,'DSA Problem Tracker'!$E:$E,"Solved")>0,INDEX('DSA Problem Tracker'!$F:$F,MATCH(C23,'DSA Problem Tracker'!$C:$C,0)),TODAY()),"")
A24: 23 | C24: Rotate Image | D24: Medium | E24: Matrix | F24: =IF(COUNTIFS('DSA Problem Tracker'!$C:$C,C24,'DSA Problem Tracker'!$E:$E,"Solved")>0,"Solved","") | G24: =IF(F24="Solved",IF(COUNTIFS('DSA Problem Tracker'!$C:$C,C24,'DSA Problem Tracker'!$E:$E,"Solved")>0,INDEX('DSA Problem Tracker'!$F:$F,MATCH(C24,'DSA Problem Tracker'!$C:$C,0)),TODAY()),"")
A25: 24 | C25: Design Twitter | D25: Medium | E25: Design | F25: =IF(COUNTIFS('DSA Problem Tracker'!$C:$C,C25,'DSA Problem Tracker'!$E:$E,"Solved")>0,"Solved","") | G25: =IF(F25="Solved",IF(COUNTIFS('DSA Problem Tracker'!$C:$C,C25,'DSA Problem Tracker'!$E:$E,"Solved")>0,INDEX('DSA Problem Tracker'!$F:$F,MATCH(C25,'DSA Problem Tracker'!$C:$C,0)),TODAY()),"")
A26: 25 | C26: Word Search | D26: Medium | E26: Backtracking | F26: =IF(COUNTIFS('DSA Problem Tracker'!$C:$C,C26,'DSA Problem Tracker'!$E:$E,"Solved")>0,"Solved","") | G26: =IF(F26="Solved",IF(COUNTIFS('DSA Problem Tracker'!$C:$C,C26,'DSA Problem Tracker'!$E:$E,"Solved")>0,INDEX('DSA Problem Tracker'!$F:$F,MATCH(C26,'DSA Problem Tracker'!$C:$C,0)),TODAY()),"")
A27: 26 | C27: Clone Graph | D27: Medium | E27: DFS | F27: =IF(COUNTIFS('DSA Problem Tracker'!$C:$C,C27,'DSA Problem Tracker'!$E:$E,"Solved")>0,"Solved","") | G27: =IF(F27="Solved",IF(COUNTIFS('DSA Problem Tracker'!$C:$C,C27,'DSA Problem Tracker'!$E:$E,"Solved")>0,INDEX('DSA Problem Tracker'!$F:$F,MATCH(C27,'DSA Problem Tracker'!$C:$C,0)),TODAY()),"")
A28: 27 | C28: Longest Palindromic Substring | D28: Medium | E28: DP | F28: =IF(COUNTIFS('DSA Problem Tracker'!$C:$C,C28,'DSA Problem Tracker'!$E:$E,"Solved")>0,"Solved","") | G28: =IF(F28="Solved",IF(COUNTIFS('DSA Problem Tracker'!$C:$C,C28,'DSA Problem Tracker'!$E:$E,"Solved")>0,INDEX('DSA Problem Tracker'!$F:$F,MATCH(C28,'DSA Problem Tracker'!$C:$C,0)),TODAY()),"")
A29: 28 | C29: Maximal Rectangle | D29: Hard | E29: Stack | F29: =IF(COUNTIFS('DSA Problem Tracker'!$C:$C,C29,'DSA Problem Tracker'!$E:$E,"Solved")>0,"Solved","") | G29: =IF(F29="Solved",IF(COUNTIFS('DSA Problem Tracker'!$C:$C,C29,'DSA Problem Tracker'!$E:$E,"Solved")>0,INDEX('DSA Problem Tracker'!$F:$F,MATCH(C29,'DSA Problem Tracker'!$C:$C,0)),TODAY()),"")
A30: 29 | C30: Course Schedule II | D30: Medium | E30: Topological Sort | F30: =IF(COUNTIFS('DSA Problem Tracker'!$C:$C,C30,'DSA Problem Tracker'!$E:$E,"Solved")>0,"Solved","") | G30: =IF(F30="Solved",IF(COUNTIFS('DSA Problem Tracker'!$C:$C,C30,'DSA Problem Tracker'!$E:$E,"Solved")>0,INDEX('DSA Problem Tracker'!$F:$F,MATCH(C30,'DSA Problem Tracker'!$C:$C,0)),TODAY()),"")
A31: 30 | C31: Lowest Common Ancestor | D31: Medium | E31: Trees | F31: =IF(COUNTIFS('DSA Problem Tracker'!$C:$C,C31,'DSA Problem Tracker'!$E:$E,"Solved")>0,"Solved","") | G31: =IF(F31="Solved",IF(COUNTIFS('DSA Problem Tracker'!$C:$C,C31,'DSA Problem Tracker'!$E:$E,"Solved")>0,INDEX('DSA Problem Tracker'!$F:$F,MATCH(C31,'DSA Problem Tracker'!$C:$C,0)),TODAY()),"")
A32: 31 | B32: Meta | C32: Valid Palindrome | D32: Easy | E32: Two Pointers | F32: =IF(COUNTIFS('DSA Problem Tracker'!$C:$C,C32,'DSA Problem Tracker'!$E:$E,"Solved")>0,"Solved","") | G32: =IF(F32="Solved",IF(COUNTIFS('DSA Problem Tracker'!$C:$C,C32,'DSA Problem Tracker'!$E:$E,"Solved")>0,INDEX('DSA Problem Tracker'!$F:$F,MATCH(C32,'DSA Problem Tracker'!$C:$C,0)),TODAY()),"")
A33: 32 | C33: Binary Tree Vertical Order Traversal | D33: Medium | E33: Trees | F33: =IF(COUNTIFS('DSA Problem Tracker'!$C:$C,C33,'DSA Problem Tracker'!$E:$E,"Solved")>0,"Solved","") | G33: =IF(F33="Solved",IF(COUNTIFS('DSA Problem Tracker'!$C:$C,C33,'DSA Problem Tracker'!$E:$E,"Solved")>0,INDEX('DSA Problem Tracker'!$F:$F,MATCH(C33,'DSA Problem Tracker'!$C:$C,0)),TODAY()),"")
A34: 33 | C34: Subarray Sum Equals K | D34: Medium | E34: Prefix Sum | F34: =IF(COUNTIFS('DSA Problem Tracker'!$C:$C,C34,'DSA Problem Tracker'!$E:$E,"Solved")>0,"Solved","") | G34: =IF(F34="Solved",IF(COUNTIFS('DSA Problem Tracker'!$C:$C,C34,'DSA Problem Tracker'!$E:$E,"Solved")>0,INDEX('DSA Problem Tracker'!$F:$F,MATCH(C34,'DSA Problem Tracker'!$C:$C,0)),TODAY()),"")
A35: 34 | C35: Merge Intervals | D35: Medium | E35: Intervals | F35: =IF(COUNTIFS('DSA Problem Tracker'!$C:$C,C35,'DSA Problem Tracker'!$E:$E,"Solved")>0,"Solved","") | G35: =IF(F35="Solved",IF(COUNTIFS('DSA Problem Tracker'!$C:$C,C35,'DSA Problem Tracker'!$E:$E,"Solved")>0,INDEX('DSA Problem Tracker'!$F:$F,MATCH(C35,'DSA Problem Tracker'!$C:$C,0)),TODAY()),"")
A36: 35 | C36: Expression Add Operators | D36: Hard | E36: Backtracking | F36: =IF(COUNTIFS('DSA Problem Tracker'!$C:$C,C36,'DSA Problem Tracker'!$E:$E,"Solved")>0,"Solved","") | G36: =IF(F36="Solved",IF(COUNTIFS('DSA Problem Tracker'!$C:$C,C36,'DSA Problem Tracker'!$E:$E,"Solved")>0,INDEX('DSA Problem Tracker'!$F:$F,MATCH(C36,'DSA Problem Tracker'!$C:$C,0)),TODAY()),"")
A37: 36 | C37: Random Pick with Weight | D37: Medium | E37: Binary Search | F37: =IF(COUNTIFS('DSA Problem Tracker'!$C:$C,C37,'DSA Problem Tracker'!$E:$E,"Solved")>0,"Solved","") | G37: =IF(F37="Solved",IF(COUNTIFS('DSA Problem Tracker'!$C:$C,C37,'DSA Problem Tracker'!$E:$E,"Solved")>0,INDEX('DSA Problem Tracker'!$F:$F,MATCH(C37,'DSA Problem Tracker'!$C:$C,0)),TODAY()),"")
A38: 37 | C38: Verifying an Alien Dictionary | D38: Easy | E38: Hash Map | F38: =IF(COUNTIFS('DSA Problem Tracker'!$C:$C,C38,'DSA Problem Tracker'!$E:$E,"Solved")>0,"Solved","") | G38: =IF(F38="Solved",IF(COUNTIFS('DSA Problem Tracker'!$C:$C,C38,'DSA Problem Tracker'!$E:$E,"Solved")>0,INDEX('DSA Problem Tracker'!$F:$F,MATCH(C38,'DSA Problem Tracker'!$C:$C,0)),TODAY()),"")
A39: 38 | C39: Buildings With Ocean View | D39: Medium | E39: Stack | F39: =IF(COUNTIFS('DSA Problem Tracker'!$C:$C,C39,'DSA Problem Tracker'!$E:$E,"Solved")>0,"Solved","") | G39: =IF(F39="Solved",IF(COUNTIFS('DSA Problem Tracker'!$C:$C,C39,'DSA Problem Tracker'!$E:$E,"Solved")>0,INDEX('DSA Problem Tracker'!$F:$F,MATCH(C39,'DSA Problem Tracker'!$C:$C,0)),TODAY()),"")
A40: 39 | C40: Minimum Remove to Make Valid Parentheses | D40: Medium | E40: Stack | F40: =IF(COUNTIFS('DSA Problem Tracker'!$C:$C,C40,'DSA Problem Tracker'!$E:$E,"Solved")>0,"Solved","") | G40: =IF(F40="Solved",IF(COUNTIFS('DSA Problem Tracker'!$C:$C,C40,'DSA Problem Tracker'!$E:$E,"Solved")>0,INDEX('DSA Problem Tracker'!$F:$F,MATCH(C40,'DSA Problem Tracker'!$C:$C,0)),TODAY()),"")
...
